[2023-12-02 19:54:58,761] {{taskinstance.py:670}} INFO - Dependencies all met for <TaskInstance: history_data_init.load_data_psql 2023-12-02T18:19:41.916238+00:00 [queued]>
[2023-12-02 19:54:58,879] {{taskinstance.py:670}} INFO - Dependencies all met for <TaskInstance: history_data_init.load_data_psql 2023-12-02T18:19:41.916238+00:00 [queued]>
[2023-12-02 19:54:58,881] {{taskinstance.py:880}} INFO - 
--------------------------------------------------------------------------------
[2023-12-02 19:54:58,883] {{taskinstance.py:881}} INFO - Starting attempt 14 of 14
[2023-12-02 19:54:58,885] {{taskinstance.py:882}} INFO - 
--------------------------------------------------------------------------------
[2023-12-02 19:54:58,917] {{taskinstance.py:901}} INFO - Executing <Task(PythonOperator): load_data_psql> on 2023-12-02T18:19:41.916238+00:00
[2023-12-02 19:54:58,926] {{standard_task_runner.py:54}} INFO - Started process 3598 to run task
[2023-12-02 19:54:59,094] {{standard_task_runner.py:77}} INFO - Running: ['airflow', 'run', 'history_data_init', 'load_data_psql', '2023-12-02T18:19:41.916238+00:00', '--job_id', '18', '--pool', 'default_pool', '--raw', '-sd', 'DAGS_FOLDER/history_data_init.py', '--cfg_path', '/tmp/tmpvqpxwz8k']
[2023-12-02 19:54:59,100] {{standard_task_runner.py:78}} INFO - Job 18: Subtask load_data_psql
[2023-12-02 19:54:59,193] {{logging_mixin.py:120}} INFO - Running <TaskInstance: history_data_init.load_data_psql 2023-12-02T18:19:41.916238+00:00 [running]> on host 4e554c5d2931
[2023-12-02 19:54:59,235] {{base_hook.py:89}} INFO - Using connection to: id: conn1. Host: host.docker.internal, Port: 5434, Schema: quotes, Login: postgres, Password: XXXXXXXX, extra: None
[2023-12-02 19:54:59,270] {{logging_mixin.py:120}} INFO - IBM
[2023-12-02 19:54:59,272] {{taskinstance.py:1150}} ERROR - '>' not supported between instances of 'datetime.date' and 'str'
Traceback (most recent call last):
  File "/usr/local/lib/python3.7/site-packages/airflow/models/taskinstance.py", line 984, in _run_raw_task
    result = task_copy.execute(context=context)
  File "/usr/local/lib/python3.7/site-packages/airflow/operators/python_operator.py", line 113, in execute
    return_value = self.execute_callable()
  File "/usr/local/lib/python3.7/site-packages/airflow/operators/python_operator.py", line 118, in execute_callable
    return self.python_callable(*self.op_args, **self.op_kwargs)
  File "/usr/local/airflow/dags/modules/functions.py", line 41, in load_data_psql
    load_data_by_time(conn, symbol)
  File "/usr/local/airflow/dags/modules/functions.py", line 47, in load_data_by_time
    while time > '1999-12-01':
TypeError: '>' not supported between instances of 'datetime.date' and 'str'
[2023-12-02 19:54:59,280] {{taskinstance.py:1194}} INFO - Marking task as FAILED. dag_id=history_data_init, task_id=load_data_psql, execution_date=20231202T181941, start_date=20231202T195458, end_date=20231202T195459
[2023-12-02 19:55:03,730] {{local_task_job.py:102}} INFO - Task exited with return code 1
