[2023-12-02 19:57:37,346] {{taskinstance.py:670}} INFO - Dependencies all met for <TaskInstance: history_data_init.load_data_psql 2023-12-02T18:19:41.916238+00:00 [queued]>
[2023-12-02 19:57:37,527] {{taskinstance.py:670}} INFO - Dependencies all met for <TaskInstance: history_data_init.load_data_psql 2023-12-02T18:19:41.916238+00:00 [queued]>
[2023-12-02 19:57:37,531] {{taskinstance.py:880}} INFO - 
--------------------------------------------------------------------------------
[2023-12-02 19:57:37,533] {{taskinstance.py:881}} INFO - Starting attempt 15 of 15
[2023-12-02 19:57:37,535] {{taskinstance.py:882}} INFO - 
--------------------------------------------------------------------------------
[2023-12-02 19:57:37,570] {{taskinstance.py:901}} INFO - Executing <Task(PythonOperator): load_data_psql> on 2023-12-02T18:19:41.916238+00:00
[2023-12-02 19:57:37,584] {{standard_task_runner.py:54}} INFO - Started process 3704 to run task
[2023-12-02 19:57:37,730] {{standard_task_runner.py:77}} INFO - Running: ['airflow', 'run', 'history_data_init', 'load_data_psql', '2023-12-02T18:19:41.916238+00:00', '--job_id', '19', '--pool', 'default_pool', '--raw', '-sd', 'DAGS_FOLDER/history_data_init.py', '--cfg_path', '/tmp/tmp5ztxaxkr']
[2023-12-02 19:57:37,733] {{standard_task_runner.py:78}} INFO - Job 19: Subtask load_data_psql
[2023-12-02 19:57:37,838] {{logging_mixin.py:120}} INFO - Running <TaskInstance: history_data_init.load_data_psql 2023-12-02T18:19:41.916238+00:00 [running]> on host 4e554c5d2931
[2023-12-02 19:57:37,906] {{base_hook.py:89}} INFO - Using connection to: id: conn1. Host: host.docker.internal, Port: 5434, Schema: quotes, Login: postgres, Password: XXXXXXXX, extra: None
[2023-12-02 19:57:37,974] {{logging_mixin.py:120}} INFO - IBM
[2023-12-02 19:57:37,987] {{taskinstance.py:1150}} ERROR - can't compare datetime.datetime to datetime.date
Traceback (most recent call last):
  File "/usr/local/lib/python3.7/site-packages/airflow/models/taskinstance.py", line 984, in _run_raw_task
    result = task_copy.execute(context=context)
  File "/usr/local/lib/python3.7/site-packages/airflow/operators/python_operator.py", line 113, in execute
    return_value = self.execute_callable()
  File "/usr/local/lib/python3.7/site-packages/airflow/operators/python_operator.py", line 118, in execute_callable
    return self.python_callable(*self.op_args, **self.op_kwargs)
  File "/usr/local/airflow/dags/modules/functions.py", line 39, in load_data_psql
    load_data_by_time(conn, symbol)
  File "/usr/local/airflow/dags/modules/functions.py", line 45, in load_data_by_time
    while time > datetime(1999, 12, 1):
TypeError: can't compare datetime.datetime to datetime.date
[2023-12-02 19:57:38,110] {{taskinstance.py:1194}} INFO - Marking task as FAILED. dag_id=history_data_init, task_id=load_data_psql, execution_date=20231202T181941, start_date=20231202T195737, end_date=20231202T195738
[2023-12-02 19:57:42,258] {{local_task_job.py:102}} INFO - Task exited with return code 1
