[2023-12-02 19:58:20,974] {{taskinstance.py:670}} INFO - Dependencies all met for <TaskInstance: history_data_init.load_data_psql 2023-12-02T18:19:41.916238+00:00 [queued]>
[2023-12-02 19:58:21,096] {{taskinstance.py:670}} INFO - Dependencies all met for <TaskInstance: history_data_init.load_data_psql 2023-12-02T18:19:41.916238+00:00 [queued]>
[2023-12-02 19:58:21,098] {{taskinstance.py:880}} INFO - 
--------------------------------------------------------------------------------
[2023-12-02 19:58:21,100] {{taskinstance.py:881}} INFO - Starting attempt 16 of 16
[2023-12-02 19:58:21,101] {{taskinstance.py:882}} INFO - 
--------------------------------------------------------------------------------
[2023-12-02 19:58:21,131] {{taskinstance.py:901}} INFO - Executing <Task(PythonOperator): load_data_psql> on 2023-12-02T18:19:41.916238+00:00
[2023-12-02 19:58:21,142] {{standard_task_runner.py:54}} INFO - Started process 3733 to run task
[2023-12-02 19:58:21,252] {{standard_task_runner.py:77}} INFO - Running: ['airflow', 'run', 'history_data_init', 'load_data_psql', '2023-12-02T18:19:41.916238+00:00', '--job_id', '20', '--pool', 'default_pool', '--raw', '-sd', 'DAGS_FOLDER/history_data_init.py', '--cfg_path', '/tmp/tmpoktyoy10']
[2023-12-02 19:58:21,255] {{standard_task_runner.py:78}} INFO - Job 20: Subtask load_data_psql
[2023-12-02 19:58:21,324] {{logging_mixin.py:120}} INFO - Running <TaskInstance: history_data_init.load_data_psql 2023-12-02T18:19:41.916238+00:00 [running]> on host 4e554c5d2931
[2023-12-02 19:58:21,364] {{base_hook.py:89}} INFO - Using connection to: id: conn1. Host: host.docker.internal, Port: 5434, Schema: quotes, Login: postgres, Password: XXXXXXXX, extra: None
[2023-12-02 19:58:21,405] {{logging_mixin.py:120}} INFO - IBM
[2023-12-02 20:00:46,200] {{local_task_job.py:159}} WARNING - State of this instance has been externally set to shutdown. Taking the poison pill.
[2023-12-02 20:00:46,204] {{helpers.py:325}} INFO - Sending Signals.SIGTERM to GPID 3733
[2023-12-02 20:00:46,221] {{taskinstance.py:955}} ERROR - Received SIGTERM. Terminating subprocesses.
[2023-12-02 20:00:46,224] {{taskinstance.py:1150}} ERROR - Ошибка записи данных: Task received SIGTERM signal
Traceback (most recent call last):
  File "/usr/local/airflow/dags/modules/functions.py", line 54, in load_data_by_symbol
    response = get_url(symbol, month)
  File "/usr/local/airflow/dags/modules/functions.py", line 31, in get_url
    'apikey': API_KEY})
  File "/usr/local/lib/python3.7/site-packages/requests/api.py", line 76, in get
    return request('get', url, params=params, **kwargs)
  File "/usr/local/lib/python3.7/site-packages/requests/api.py", line 61, in request
    return session.request(method=method, url=url, **kwargs)
  File "/usr/local/lib/python3.7/site-packages/requests/sessions.py", line 530, in request
    resp = self.send(prep, **send_kwargs)
  File "/usr/local/lib/python3.7/site-packages/requests/sessions.py", line 643, in send
    r = adapter.send(request, **kwargs)
  File "/usr/local/lib/python3.7/site-packages/requests/adapters.py", line 449, in send
    timeout=timeout
  File "/usr/local/lib/python3.7/site-packages/urllib3/connectionpool.py", line 677, in urlopen
    chunked=chunked,
  File "/usr/local/lib/python3.7/site-packages/urllib3/connectionpool.py", line 381, in _make_request
    self._validate_conn(conn)
  File "/usr/local/lib/python3.7/site-packages/urllib3/connectionpool.py", line 978, in _validate_conn
    conn.connect()
  File "/usr/local/lib/python3.7/site-packages/urllib3/connection.py", line 371, in connect
    ssl_context=context,
  File "/usr/local/lib/python3.7/site-packages/urllib3/util/ssl_.py", line 352, in ssl_wrap_socket
    context.load_verify_locations(ca_certs, ca_cert_dir, ca_cert_data)
  File "/usr/local/lib/python3.7/site-packages/airflow/models/taskinstance.py", line 957, in signal_handler
    raise AirflowException("Task received SIGTERM signal")
airflow.exceptions.AirflowException: Task received SIGTERM signal

During handling of the above exception, another exception occurred:

Traceback (most recent call last):
  File "/usr/local/lib/python3.7/site-packages/airflow/models/taskinstance.py", line 984, in _run_raw_task
    result = task_copy.execute(context=context)
  File "/usr/local/lib/python3.7/site-packages/airflow/operators/python_operator.py", line 113, in execute
    return_value = self.execute_callable()
  File "/usr/local/lib/python3.7/site-packages/airflow/operators/python_operator.py", line 118, in execute_callable
    return self.python_callable(*self.op_args, **self.op_kwargs)
  File "/usr/local/airflow/dags/modules/functions.py", line 39, in load_data_psql
    load_data_by_time(conn, symbol)
  File "/usr/local/airflow/dags/modules/functions.py", line 47, in load_data_by_time
    load_data_by_symbol(conn, symbol, month)
  File "/usr/local/airflow/dags/modules/functions.py", line 76, in load_data_by_symbol
    raise Exception(f'Ошибка записи данных: {error}')
Exception: Ошибка записи данных: Task received SIGTERM signal
[2023-12-02 20:00:46,250] {{taskinstance.py:1194}} INFO - Marking task as FAILED. dag_id=history_data_init, task_id=load_data_psql, execution_date=20231202T181941, start_date=20231202T195820, end_date=20231202T200046
[2023-12-02 20:00:46,339] {{helpers.py:291}} INFO - Process psutil.Process(pid=3733, status='terminated', exitcode=1, started='19:58:20') (3733) terminated with exit code 1
[2023-12-02 20:00:46,343] {{local_task_job.py:102}} INFO - Task exited with return code 1
