[2023-12-02 18:15:22,289] {{taskinstance.py:670}} INFO - Dependencies all met for <TaskInstance: history_data_init.create_tables 2023-12-02T18:13:48.498197+00:00 [queued]>
[2023-12-02 18:15:22,476] {{taskinstance.py:670}} INFO - Dependencies all met for <TaskInstance: history_data_init.create_tables 2023-12-02T18:13:48.498197+00:00 [queued]>
[2023-12-02 18:15:22,488] {{taskinstance.py:880}} INFO - 
--------------------------------------------------------------------------------
[2023-12-02 18:15:22,516] {{taskinstance.py:881}} INFO - Starting attempt 2 of 2
[2023-12-02 18:15:22,518] {{taskinstance.py:882}} INFO - 
--------------------------------------------------------------------------------
[2023-12-02 18:15:22,551] {{taskinstance.py:901}} INFO - Executing <Task(PostgresOperator): create_tables> on 2023-12-02T18:13:48.498197+00:00
[2023-12-02 18:15:22,562] {{standard_task_runner.py:54}} INFO - Started process 5622 to run task
[2023-12-02 18:15:22,685] {{standard_task_runner.py:77}} INFO - Running: ['airflow', 'run', 'history_data_init', 'create_tables', '2023-12-02T18:13:48.498197+00:00', '--job_id', '32', '--pool', 'default_pool', '--raw', '-sd', 'DAGS_FOLDER/history_data_init.py', '--cfg_path', '/tmp/tmp1r4kxxb6']
[2023-12-02 18:15:22,687] {{standard_task_runner.py:78}} INFO - Job 32: Subtask create_tables
[2023-12-02 18:15:22,761] {{logging_mixin.py:120}} INFO - Running <TaskInstance: history_data_init.create_tables 2023-12-02T18:13:48.498197+00:00 [running]> on host 2cf373442eb7
[2023-12-02 18:15:22,803] {{taskinstance.py:1150}} ERROR - [Errno 2] No such file or directory: '/usr/local/airflow/dags/sql/create_stock_quotes.sql'
Traceback (most recent call last):
  File "/usr/local/lib/python3.7/site-packages/airflow/models/taskinstance.py", line 965, in _run_raw_task
    self.render_templates(context=context)
  File "/usr/local/lib/python3.7/site-packages/airflow/models/taskinstance.py", line 1424, in render_templates
    self.task.render_template_fields(context)
  File "/usr/local/lib/python3.7/site-packages/airflow/models/baseoperator.py", line 719, in render_template_fields
    self._do_render_template_fields(self, self.template_fields, context, jinja_env, set())
  File "/usr/local/lib/python3.7/site-packages/airflow/models/baseoperator.py", line 726, in _do_render_template_fields
    rendered_content = self.render_template(content, context, jinja_env, seen_oids)
  File "/usr/local/lib/python3.7/site-packages/airflow/models/baseoperator.py", line 753, in render_template
    return jinja_env.get_template(content).render(**context)
  File "/usr/local/lib/python3.7/site-packages/jinja2/environment.py", line 883, in get_template
    return self._load_template(name, self.make_globals(globals))
  File "/usr/local/lib/python3.7/site-packages/jinja2/environment.py", line 857, in _load_template
    template = self.loader.load(self, name, globals)
  File "/usr/local/lib/python3.7/site-packages/jinja2/loaders.py", line 115, in load
    source, filename, uptodate = self.get_source(environment, name)
  File "/usr/local/lib/python3.7/site-packages/jinja2/loaders.py", line 180, in get_source
    f = open_if_exists(filename)
  File "/usr/local/lib/python3.7/site-packages/jinja2/utils.py", line 144, in open_if_exists
    return open(filename, mode)
FileNotFoundError: [Errno 2] No such file or directory: '/usr/local/airflow/dags/sql/create_stock_quotes.sql'
[2023-12-02 18:15:22,814] {{taskinstance.py:1194}} INFO - Marking task as FAILED. dag_id=history_data_init, task_id=create_tables, execution_date=20231202T181348, start_date=20231202T181522, end_date=20231202T181522
[2023-12-02 18:15:27,222] {{local_task_job.py:102}} INFO - Task exited with return code 1
