[2023-12-02 17:34:49,047] {{taskinstance.py:670}} INFO - Dependencies all met for <TaskInstance: hw-3.4.load_data_psql 2023-12-02T15:52:55.287974+00:00 [queued]>
[2023-12-02 17:34:49,406] {{taskinstance.py:670}} INFO - Dependencies all met for <TaskInstance: hw-3.4.load_data_psql 2023-12-02T15:52:55.287974+00:00 [queued]>
[2023-12-02 17:34:49,429] {{taskinstance.py:880}} INFO - 
--------------------------------------------------------------------------------
[2023-12-02 17:34:49,450] {{taskinstance.py:881}} INFO - Starting attempt 18 of 18
[2023-12-02 17:34:49,474] {{taskinstance.py:882}} INFO - 
--------------------------------------------------------------------------------
[2023-12-02 17:34:49,637] {{taskinstance.py:901}} INFO - Executing <Task(PythonOperator): load_data_psql> on 2023-12-02T15:52:55.287974+00:00
[2023-12-02 17:34:49,687] {{standard_task_runner.py:54}} INFO - Started process 4075 to run task
[2023-12-02 17:34:49,947] {{standard_task_runner.py:77}} INFO - Running: ['airflow', 'run', 'hw-3.4', 'load_data_psql', '2023-12-02T15:52:55.287974+00:00', '--job_id', '27', '--pool', 'default_pool', '--raw', '-sd', 'DAGS_FOLDER/hw-3.4.py', '--cfg_path', '/tmp/tmp1w2kfyvw']
[2023-12-02 17:34:49,966] {{standard_task_runner.py:78}} INFO - Job 27: Subtask load_data_psql
[2023-12-02 17:34:50,489] {{logging_mixin.py:120}} INFO - Running <TaskInstance: hw-3.4.load_data_psql 2023-12-02T15:52:55.287974+00:00 [running]> on host 2cf373442eb7
[2023-12-02 17:34:50,750] {{base_hook.py:89}} INFO - Using connection to: id: conn1. Host: host.docker.internal, Port: 5434, Schema: quotes, Login: postgres, Password: XXXXXXXX, extra: None
[2023-12-02 17:34:52,654] {{logging_mixin.py:120}} INFO - ------------ response --------------
[2023-12-02 17:34:52,661] {{logging_mixin.py:120}} INFO - https://www.alphavantage.co/?function=SYMBOL_SEARCH&apikey=XFXOO5DWCE1OF11E&keywords=Netflix
[2023-12-02 17:34:52,663] {{logging_mixin.py:120}} INFO - None
[2023-12-02 17:34:52,665] {{logging_mixin.py:120}} INFO - {'User-Agent': 'python-requests/2.23.0', 'Accept-Encoding': 'gzip, deflate', 'Accept': '*/*', 'Connection': 'keep-alive'}
[2023-12-02 17:34:52,667] {{logging_mixin.py:120}} INFO - ------------ end --------------
[2023-12-02 17:34:52,670] {{taskinstance.py:1150}} ERROR - Ошибка записи данных: Expecting value: line 1 column 1 (char 0)
Traceback (most recent call last):
  File "/usr/local/airflow/dags/modules/functions.py", line 50, in load_data_psql
    data = response.json()
  File "/usr/local/lib/python3.7/site-packages/requests/models.py", line 898, in json
    return complexjson.loads(self.text, **kwargs)
  File "/usr/local/lib/python3.7/json/__init__.py", line 348, in loads
    return _default_decoder.decode(s)
  File "/usr/local/lib/python3.7/json/decoder.py", line 337, in decode
    obj, end = self.raw_decode(s, idx=_w(s, 0).end())
  File "/usr/local/lib/python3.7/json/decoder.py", line 355, in raw_decode
    raise JSONDecodeError("Expecting value", s, err.value) from None
json.decoder.JSONDecodeError: Expecting value: line 1 column 1 (char 0)

During handling of the above exception, another exception occurred:

Traceback (most recent call last):
  File "/usr/local/lib/python3.7/site-packages/airflow/models/taskinstance.py", line 984, in _run_raw_task
    result = task_copy.execute(context=context)
  File "/usr/local/lib/python3.7/site-packages/airflow/operators/python_operator.py", line 113, in execute
    return_value = self.execute_callable()
  File "/usr/local/lib/python3.7/site-packages/airflow/operators/python_operator.py", line 118, in execute_callable
    return self.python_callable(*self.op_args, **self.op_kwargs)
  File "/usr/local/airflow/dags/modules/functions.py", line 67, in load_data_psql
    raise Exception(f'Ошибка записи данных: {error}')
Exception: Ошибка записи данных: Expecting value: line 1 column 1 (char 0)
[2023-12-02 17:34:52,701] {{taskinstance.py:1194}} INFO - Marking task as FAILED. dag_id=hw-3.4, task_id=load_data_psql, execution_date=20231202T155255, start_date=20231202T173449, end_date=20231202T173452
[2023-12-02 17:34:53,752] {{local_task_job.py:102}} INFO - Task exited with return code 1
