[2023-12-02 16:27:13,250] {{taskinstance.py:670}} INFO - Dependencies all met for <TaskInstance: hw-3.4.load_data_psql 2023-12-02T15:52:55.287974+00:00 [queued]>
[2023-12-02 16:27:13,418] {{taskinstance.py:670}} INFO - Dependencies all met for <TaskInstance: hw-3.4.load_data_psql 2023-12-02T15:52:55.287974+00:00 [queued]>
[2023-12-02 16:27:13,421] {{taskinstance.py:880}} INFO - 
--------------------------------------------------------------------------------
[2023-12-02 16:27:13,423] {{taskinstance.py:881}} INFO - Starting attempt 5 of 5
[2023-12-02 16:27:13,425] {{taskinstance.py:882}} INFO - 
--------------------------------------------------------------------------------
[2023-12-02 16:27:13,461] {{taskinstance.py:901}} INFO - Executing <Task(PythonOperator): load_data_psql> on 2023-12-02T15:52:55.287974+00:00
[2023-12-02 16:27:13,471] {{standard_task_runner.py:54}} INFO - Started process 1484 to run task
[2023-12-02 16:27:13,638] {{standard_task_runner.py:77}} INFO - Running: ['airflow', 'run', 'hw-3.4', 'load_data_psql', '2023-12-02T15:52:55.287974+00:00', '--job_id', '14', '--pool', 'default_pool', '--raw', '-sd', 'DAGS_FOLDER/hw-3.4.py', '--cfg_path', '/tmp/tmps_wvmbn2']
[2023-12-02 16:27:13,642] {{standard_task_runner.py:78}} INFO - Job 14: Subtask load_data_psql
[2023-12-02 16:27:13,734] {{logging_mixin.py:120}} INFO - Running <TaskInstance: hw-3.4.load_data_psql 2023-12-02T15:52:55.287974+00:00 [running]> on host 2cf373442eb7
[2023-12-02 16:27:13,779] {{base_hook.py:89}} INFO - Using connection to: id: conn1. Host: host.docker.internal, Port: 5434, Schema: quotes, Login: postgres, Password: XXXXXXXX, extra: None
[2023-12-02 16:27:14,369] {{logging_mixin.py:120}} INFO - ------------ response --------------
[2023-12-02 16:27:14,372] {{logging_mixin.py:120}} INFO - https://www.alphavantage.co/query?function=SYMBOL_SEARCH&apikey=PO8LZ4A0I0PPI60J&keywords=tesco
[2023-12-02 16:27:14,375] {{logging_mixin.py:120}} INFO - None
[2023-12-02 16:27:14,377] {{logging_mixin.py:120}} INFO - {'User-Agent': 'python-requests/2.23.0', 'Accept-Encoding': 'gzip, deflate', 'Accept': '*/*', 'Connection': 'keep-alive'}
[2023-12-02 16:27:14,378] {{logging_mixin.py:120}} INFO - ------------ end --------------
[2023-12-02 16:27:14,380] {{logging_mixin.py:120}} INFO - ------------ data --------------
[2023-12-02 16:27:14,382] {{logging_mixin.py:120}} INFO - {'bestMatches': [{'1. symbol': 'TSCO.LON', '2. name': 'Tesco PLC', '3. type': 'Equity', '4. region': 'United Kingdom', '5. marketOpen': '08:00', '6. marketClose': '16:30', '7. timezone': 'UTC+01', '8. currency': 'GBX', '9. matchScore': '0.7273'}, {'1. symbol': 'TSCDF', '2. name': 'Tesco plc', '3. type': 'Equity', '4. region': 'United States', '5. marketOpen': '09:30', '6. marketClose': '16:00', '7. timezone': 'UTC-04', '8. currency': 'USD', '9. matchScore': '0.7143'}, {'1. symbol': 'TSCDY', '2. name': 'Tesco plc', '3. type': 'Equity', '4. region': 'United States', '5. marketOpen': '09:30', '6. marketClose': '16:00', '7. timezone': 'UTC-04', '8. currency': 'USD', '9. matchScore': '0.7143'}, {'1. symbol': 'TCO2.FRK', '2. name': 'TESCO PLC ADR/1 LS-05', '3. type': 'Equity', '4. region': 'Frankfurt', '5. marketOpen': '08:00', '6. marketClose': '20:00', '7. timezone': 'UTC+02', '8. currency': 'EUR', '9. matchScore': '0.5455'}, {'1. symbol': 'TCO0.FRK', '2. name': 'TESCO PLC LS-0633333', '3. type': 'Equity', '4. region': 'Frankfurt', '5. marketOpen': '08:00', '6. marketClose': '20:00', '7. timezone': 'UTC+02', '8. currency': 'EUR', '9. matchScore': '0.5455'}]}
[2023-12-02 16:27:14,383] {{logging_mixin.py:120}} INFO - ------------ end --------------
[2023-12-02 16:27:14,385] {{taskinstance.py:1150}} ERROR - Ошибка записи данных: 'timestamp'
Traceback (most recent call last):
  File "/usr/local/airflow/dags/modules/functions.py", line 70, in load_data_psql
    get_date = datetime.utcfromtimestamp(data["timestamp"]).strftime('%Y-%m-%d %H:%M:%S')
KeyError: 'timestamp'

During handling of the above exception, another exception occurred:

Traceback (most recent call last):
  File "/usr/local/lib/python3.7/site-packages/airflow/models/taskinstance.py", line 984, in _run_raw_task
    result = task_copy.execute(context=context)
  File "/usr/local/lib/python3.7/site-packages/airflow/operators/python_operator.py", line 113, in execute
    return_value = self.execute_callable()
  File "/usr/local/lib/python3.7/site-packages/airflow/operators/python_operator.py", line 118, in execute_callable
    return self.python_callable(*self.op_args, **self.op_kwargs)
  File "/usr/local/airflow/dags/modules/functions.py", line 83, in load_data_psql
    raise Exception(f'Ошибка записи данных: {error}')
Exception: Ошибка записи данных: 'timestamp'
[2023-12-02 16:27:14,394] {{taskinstance.py:1194}} INFO - Marking task as FAILED. dag_id=hw-3.4, task_id=load_data_psql, execution_date=20231202T155255, start_date=20231202T162713, end_date=20231202T162714
[2023-12-02 16:27:18,185] {{local_task_job.py:102}} INFO - Task exited with return code 1
